<?xml version="1.0"?>
<robot xmlns:xacro="http://www.ros.org/wiki/xacro" name="holder">

  <xacro:macro name="ee" params="connected_to:='' rpy:='0 0 0' xyz:='0 0 0' arm_id:='panda' gazebo:=true">

    <!-- TODO: Renamed to hand link/joint, because franka_hw_sim looks for this name to extract mass/inertias. -->
    <xacro:unless value="${connected_to == ''}">
      <joint name="${arm_id}_hand_joint" type="fixed">
        <parent link="${connected_to}" />
        <child link="${arm_id}_hand" />
        <origin xyz="${xyz}" rpy="${rpy}" />
      </joint>
    </xacro:unless>

    <material name="white">
      <color rgba="0.8 0.8 0.8 1.0" />
    </material>

    <!-- ee link -->
    <link name="${arm_id}_hand">
      <visual>
        <origin xyz="0 0 0" rpy="0 0 ${pi}" />
        <geometry>
          <mesh filename="package://albert_description/meshes/vacuum_plus_bracket.dae" scale="0.001 0.001 0.001" />
        </geometry>
        <material name="white" />
      </visual>
      <collision>
        <origin xyz="0 0 0" rpy="0 0 ${pi}" />
        <geometry>
          <mesh filename="package://albert_description/meshes/vacuum_plus_bracket.dae" scale="0.001 0.001 0.001" />
        </geometry>
      </collision>
      <!-- same inertia as gripper (copied from franka_ros) -->
      <xacro:if value="${gazebo}">
        <inertial>
          <mass value="0.73" />
          <origin xyz="-0.01 0 0.03" />
          <inertia ixx="0.001" ixy="0"      ixz="0"
                               iyy="0.0025" iyz="0"
                                            izz="0.0017" />
        </inertial>
      </xacro:if>
    </link>

    <joint name="${arm_id}_vacuum_joint" type="fixed">
      <parent link="${arm_id}_hand" />
      <child link="${arm_id}_vacuum" />
      <origin xyz="0 0 0.33" rpy="0 0 0" />
    </joint>

    <gazebo reference="${arm_id}_vacuum_joint">
      <disableFixedJointLumping>true</disableFixedJointLumping> 
      <preserveFixedJoint>true</preserveFixedJoint>
    </gazebo>

    <joint name="${arm_id}_vacuum_joint_2" type="fixed">
      <parent link="${arm_id}_hand" />
      <child link="${arm_id}_vacuum_2" />
      <origin xyz="0 0 0.25" rpy="0 0 0" />
    </joint>

    <link name="${arm_id}_vacuum">
      <inertial>
        <origin xyz='0.0 0.0 0.0' rpy='0.0 0.0 0.0'/>
        <mass value='0.001'/>
        <inertia ixx='0.001' ixy='0.0' ixz='0.0'
                 iyy='0.001' iyz='0.0' izz='0.001'/>
      </inertial>
    </link>

    <link name="${arm_id}_vacuum_2">
    </link>

    <!-- Simulate the inertia of the fingers -->
    <xacro:if value="${gazebo}">
      <xacro:include filename="$(find franka_description)/robots/utils.xacro"/>
      <link name="${arm_id}_rightfinger">
        <xacro:inertia-cylinder mass="15e-3" radius="0.01" h="0.04"/>
      </link>

      <link name="${arm_id}_leftfinger">
        <xacro:inertia-cylinder mass="15e-3" radius="0.01" h="0.04"/>
      </link>

      <xacro:gazebo-friction link="${arm_id}_leftfinger" mu="1.13" />
      <xacro:gazebo-friction link="${arm_id}_rightfinger" mu="1.13" />

      <joint name="${arm_id}_finger_joint1" type="prismatic">
        <parent link="${arm_id}_hand"/>
        <child link="${arm_id}_leftfinger"/>
        <origin xyz="0 0 0.0584" rpy="0 0 0"/>
        <axis xyz="0 1 0"/>
        <limit effort="100" lower="0.0" upper="0.04" velocity="0.2"/>
        <dynamics friction="0.0" damping="0.03"/>
      </joint>

      <joint name="${arm_id}_finger_joint2" type="prismatic">
        <parent link="${arm_id}_hand"/>
        <child link="${arm_id}_rightfinger"/>
        <origin xyz="0 0 0.0584" rpy="0 0 0"/>
        <axis xyz="0 -1 0"/>
        <limit effort="100" lower="0.0" upper="0.04" velocity="0.2"/>
        <dynamics friction="0.0" damping="0.03"/>
        <mimic joint="${arm_id}_finger_joint1" />
      </joint>
    </xacro:if>

    <xacro:include filename="$(find albert_description)/urdf/_d435.urdf.xacro" />
    <xacro:sensor_d435 gazebo="$(arg gazebo)" topics_ns="realsense_435" parent="${arm_id}_link8" use_nominal_extrinsics="true">
        <origin xyz="0.1052022 0.04861002 0.02188261" rpy="-0.08220003 -0.01235345  2.33171179"/>
    </xacro:sensor_d435>

  </xacro:macro>
</robot>
